<?xml version="1.0"?>
<sdf version="1.9">
  <model name="home_bot">
    <pose>0 0 0.12 0 0 0</pose>
    <self_collide>false</self_collide>

    <link name="base_link">
      <pose>0 0 0.14 0 0 0</pose>
      <inertial>
        <mass>8.0</mass>
        <inertia>
          <ixx>0.12</ixx>
          <iyy>0.18</iyy>
          <izz>0.22</izz>
          <ixy>0</ixy>
          <ixz>0</ixz>
          <iyz>0</iyz>
        </inertia>
      </inertial>
      <collision name="base_collision">
        <geometry>
          <box>
            <size>0.42 0.32 0.16</size>
          </box>
        </geometry>
      </collision>
      <visual name="base_visual">
        <geometry>
          <box>
            <size>0.42 0.32 0.16</size>
          </box>
        </geometry>
        <material>
          <diffuse>0.1 0.35 0.8 1</diffuse>
        </material>
      </visual>
      <visual name="front_marker_visual">
        <pose>0.245 0 0.035 0 0 0</pose>
        <geometry>
          <box>
            <size>0.07 0.20 0.07</size>
          </box>
        </geometry>
        <material>
          <diffuse>0.9 0.05 0.02 1</diffuse>
        </material>
      </visual>
    </link>

    <link name="left_wheel">
      <pose>0 0.19 0.08 1.570796 0 0</pose>
      <inertial>
        <mass>0.5</mass>
        <inertia>
          <ixx>0.001</ixx>
          <iyy>0.001</iyy>
          <izz>0.001</izz>
          <ixy>0</ixy>
          <ixz>0</ixz>
          <iyz>0</iyz>
        </inertia>
      </inertial>
      <collision name="left_wheel_collision">
        <geometry>
          <cylinder>
            <radius>0.075</radius>
            <length>0.045</length>
          </cylinder>
        </geometry>
        <surface>
          <friction>
            <ode>
              <mu>1.0</mu>
              <mu2>1.0</mu2>
            </ode>
          </friction>
        </surface>
      </collision>
      <visual name="left_wheel_visual">
        <geometry>
          <cylinder>
            <radius>0.075</radius>
            <length>0.045</length>
          </cylinder>
        </geometry>
        <material>
          <diffuse>0.02 0.02 0.02 1</diffuse>
        </material>
      </visual>
    </link>

    <link name="right_wheel">
      <pose>0 -0.19 0.08 1.570796 0 0</pose>
      <inertial>
        <mass>0.5</mass>
        <inertia>
          <ixx>0.001</ixx>
          <iyy>0.001</iyy>
          <izz>0.001</izz>
          <ixy>0</ixy>
          <ixz>0</ixz>
          <iyz>0</iyz>
        </inertia>
      </inertial>
      <collision name="right_wheel_collision">
        <geometry>
          <cylinder>
            <radius>0.075</radius>
            <length>0.045</length>
          </cylinder>
        </geometry>
        <surface>
          <friction>
            <ode>
              <mu>1.0</mu>
              <mu2>1.0</mu2>
            </ode>
          </friction>
        </surface>
      </collision>
      <visual name="right_wheel_visual">
        <geometry>
          <cylinder>
            <radius>0.075</radius>
            <length>0.045</length>
          </cylinder>
        </geometry>
        <material>
          <diffuse>0.02 0.02 0.02 1</diffuse>
        </material>
      </visual>
    </link>

    <link name="caster">
      <pose>-0.16 0 0.04 0 0 0</pose>
      <collision name="caster_collision">
        <geometry>
          <sphere>
            <radius>0.04</radius>
          </sphere>
        </geometry>
      </collision>
      <visual name="caster_visual">
        <geometry>
          <sphere>
            <radius>0.04</radius>
          </sphere>
        </geometry>
        <material>
          <diffuse>0.05 0.05 0.05 1</diffuse>
        </material>
      </visual>
    </link>

    <link name="imu_link">
      <pose>0 0 0.24 0 0 0</pose>
      <sensor name="imu_sensor" type="imu">
        <always_on>true</always_on>
        <update_rate>100</update_rate>
        <topic>/imu/data</topic>
      </sensor>
    </link>

    <link name="camera_link">
      <pose>0.24 0 0.34 0 0 0</pose>
      <visual name="camera_visual">
        <geometry>
          <box>
            <size>0.08 0.16 0.06</size>
          </box>
        </geometry>
        <material>
          <diffuse>0.02 0.02 0.02 1</diffuse>
        </material>
      </visual>
      <sensor name="rgbd_camera" type="rgbd_camera">
        <always_on>true</always_on>
        <update_rate>8</update_rate>
        <topic>/camera</topic>
        <camera>
          <horizontal_fov>1.3962634</horizontal_fov>
          <image>
            <width>120</width>
            <height>90</height>
            <format>R8G8B8</format>
          </image>
          <clip>
            <near>0.12</near>
            <far>5.0</far>
          </clip>
          <depth_camera>
            <clip>
              <near>0.12</near>
              <far>5.0</far>
            </clip>
          </depth_camera>
        </camera>
      </sensor>
    </link>

    <joint name="left_wheel_joint" type="revolute">
      <parent>base_link</parent>
      <child>left_wheel</child>
      <axis>
        <xyz>0 0 1</xyz>
        <limit>
          <lower>-1e16</lower>
          <upper>1e16</upper>
        </limit>
      </axis>
    </joint>

    <joint name="right_wheel_joint" type="revolute">
      <parent>base_link</parent>
      <child>right_wheel</child>
      <axis>
        <xyz>0 0 1</xyz>
        <limit>
          <lower>-1e16</lower>
          <upper>1e16</upper>
        </limit>
      </axis>
    </joint>

    <joint name="caster_joint" type="fixed">
      <parent>base_link</parent>
      <child>caster</child>
    </joint>

    <joint name="imu_joint" type="fixed">
      <parent>base_link</parent>
      <child>imu_link</child>
    </joint>

    <joint name="camera_joint" type="fixed">
      <parent>base_link</parent>
      <child>camera_link</child>
    </joint>

    <plugin filename="ignition-gazebo-diff-drive-system" name="ignition::gazebo::v6::systems::DiffDrive">
      <left_joint>left_wheel_joint</left_joint>
      <right_joint>right_wheel_joint</right_joint>
      <wheel_separation>0.38</wheel_separation>
      <wheel_radius>0.075</wheel_radius>
      <odom_publish_frequency>50</odom_publish_frequency>
      <topic>/cmd_vel_gz</topic>
      <odom_topic>/odom</odom_topic>
      <tf_topic>/tf</tf_topic>
      <frame_id>odom</frame_id>
      <child_frame_id>base_link</child_frame_id>
    </plugin>

    <plugin filename="ignition-gazebo-joint-state-publisher-system" name="ignition::gazebo::v6::systems::JointStatePublisher">
      <topic>/joint_states</topic>
      <joint_name>left_wheel_joint</joint_name>
      <joint_name>right_wheel_joint</joint_name>
    </plugin>

    <plugin filename="ignition-gazebo-pose-publisher-system" name="ignition::gazebo::v6::systems::PosePublisher">
      <publish_model_pose>true</publish_model_pose>
      <publish_link_pose>false</publish_link_pose>
      <publish_collision_pose>false</publish_collision_pose>
      <publish_visual_pose>false</publish_visual_pose>
      <publish_sensor_pose>false</publish_sensor_pose>
      <publish_nested_model_pose>false</publish_nested_model_pose>
    </plugin>
  </model>
</sdf>
